2023-12-28 00:44:12 | ERROR    | hcaptcha_challenger.onnx.modelhub:flush_runtime_assets:190 | 0 - {}
2023-12-28 00:44:29 | ERROR    | __main__:run:158 | An error has been caught in function 'run', process 'MainProcess' (3596), thread 'MainThread' (139798052400000): - {}
Traceback (most recent call last):
  File "/home/runner/work/epic-game/epic-game/epic/src/claim.py", line 162, in <module>
    asyncio.run(run())
  File "/opt/hostedtoolcache/Python/3.10.13/x64/lib/python3.10/asyncio/runners.py", line 44, in run
    return loop.run_until_complete(main)
  File "/opt/hostedtoolcache/Python/3.10.13/x64/lib/python3.10/asyncio/base_events.py", line 636, in run_until_complete
    self.run_forever()
  File "/opt/hostedtoolcache/Python/3.10.13/x64/lib/python3.10/asyncio/base_events.py", line 603, in run_forever
    self._run_once()
  File "/opt/hostedtoolcache/Python/3.10.13/x64/lib/python3.10/asyncio/base_events.py", line 1909, in _run_once
    handle._run()
  File "/opt/hostedtoolcache/Python/3.10.13/x64/lib/python3.10/asyncio/events.py", line 80, in _run
    self._context.run(self._callback, *self._args)
> File "/home/runner/work/epic-game/epic-game/epic/src/claim.py", line 158, in run
    await agent.stash()
  File "/home/runner/work/epic-game/epic-game/epic/src/claim.py", line 151, in stash
    await self.claim_epic_games(context)
  File "/home/runner/work/epic-game/epic-game/epic/src/claim.py", line 122, in claim_epic_games
    await epic.claim_weekly_games(page, single_promotions)
  File "/opt/hostedtoolcache/Python/3.10.13/x64/lib/python3.10/site-packages/tenacity/_asyncio.py", line 88, in async_wrapped
    return await fn(*args, **kwargs)
  File "/opt/hostedtoolcache/Python/3.10.13/x64/lib/python3.10/site-packages/tenacity/_asyncio.py", line 47, in __call__
    do = self.iter(retry_state=retry_state)
  File "/opt/hostedtoolcache/Python/3.10.13/x64/lib/python3.10/site-packages/tenacity/__init__.py", line 314, in iter
    return fut.result()
  File "/opt/hostedtoolcache/Python/3.10.13/x64/lib/python3.10/concurrent/futures/_base.py", line 451, in result
    return self.__get_result()
  File "/opt/hostedtoolcache/Python/3.10.13/x64/lib/python3.10/concurrent/futures/_base.py", line 403, in __get_result
    raise self._exception
  File "/opt/hostedtoolcache/Python/3.10.13/x64/lib/python3.10/site-packages/tenacity/_asyncio.py", line 50, in __call__
    result = await fn(*args, **kwargs)
  File "/home/runner/work/epic-game/epic-game/epic/src/epic_games/agent.py", line 335, in claim_weekly_games
    await self.handle.insert_challenge(self._solver, page, wpc, payment_btn, recur_url, is_uk)
  File "/opt/hostedtoolcache/Python/3.10.13/x64/lib/python3.10/site-packages/tenacity/_asyncio.py", line 88, in async_wrapped
    return await fn(*args, **kwargs)
  File "/opt/hostedtoolcache/Python/3.10.13/x64/lib/python3.10/site-packages/tenacity/_asyncio.py", line 47, in __call__
    do = self.iter(retry_state=retry_state)
  File "/opt/hostedtoolcache/Python/3.10.13/x64/lib/python3.10/site-packages/tenacity/__init__.py", line 314, in iter
    return fut.result()
  File "/opt/hostedtoolcache/Python/3.10.13/x64/lib/python3.10/concurrent/futures/_base.py", line 451, in result
    return self.__get_result()
  File "/opt/hostedtoolcache/Python/3.10.13/x64/lib/python3.10/concurrent/futures/_base.py", line 403, in __get_result
    raise self._exception
  File "/opt/hostedtoolcache/Python/3.10.13/x64/lib/python3.10/site-packages/tenacity/_asyncio.py", line 50, in __call__
    result = await fn(*args, **kwargs)
  File "/home/runner/work/epic-game/epic-game/epic/src/epic_games/agent.py", line 105, in insert_challenge
    response = await solver.execute(window="free")
  File "/opt/hostedtoolcache/Python/3.10.13/x64/lib/python3.10/site-packages/hcaptcha_challenger/agents/playwright/control.py", line 642, in execute
    await self._catch_all_binary_challenge(frame_challenge)
  File "/opt/hostedtoolcache/Python/3.10.13/x64/lib/python3.10/site-packages/hcaptcha_challenger/agents/playwright/control.py", line 486, in _catch_all_binary_challenge
    results = tool(model, image=Image.open(example_path))
  File "/opt/hostedtoolcache/Python/3.10.13/x64/lib/python3.10/site-packages/hcaptcha_challenger/components/zero_shot_image_classifier.py", line 139, in __call__
    predictions = detector(image, candidate_labels=self.candidate_labels)
  File "/opt/hostedtoolcache/Python/3.10.13/x64/lib/python3.10/site-packages/hcaptcha_challenger/onnx/clip.py", line 411, in __call__
    image_features = self.encode_image(images)
  File "/opt/hostedtoolcache/Python/3.10.13/x64/lib/python3.10/site-packages/hcaptcha_challenger/onnx/clip.py", line 375, in encode_image
    input_name = self.visual_session.get_inputs()[0].name
AttributeError: 'NoneType' object has no attribute 'get_inputs'
